Workbook

Sheet DailySales
A1: Category | B1: Item | C1: Price | D1: Cash Qty | E1: Cash Sales | F1: GCash Qty | G1: GCash Sales | H1: Foodpanda Qty | I1: Foodpanda Sales | J1: Total Qty | K1: Total Sales | L1: Date
A2: Ala Carte | B2: Korean Spicy Chicken | C2: 189 | E2: =C2*D2 -> 0 | G2: =C2*F2 -> 0 | I2: =C2*H2 -> 0 | J2: =D2+F2+H2 -> 0 | K2: =E2+G2+I2 -> 0
A3: Ala Carte | B3: Korean Spicy Pork | C3: 189 | E3: =C3*D3 -> 0 | F3: 1 | G3: =C3*F3 -> 189 | I3: =C3*H3 -> 0 | J3: =D3+F3+H3 -> 1 | K3: =E3+G3+I3 -> 189
A4: Ala Carte | B4: Beef Bulgogi | C4: 189 | E4: =C4*D4 -> 0 | G4: =C4*F4 -> 0 | I4: =C4*H4 -> 0 | J4: =D4+F4+H4 -> 0 | K4: =E4+G4+I4 -> 0
A5: Ala Carte | B5: Teokbokki (Rice cake) | C5: 189 | E5: =C5*D5 -> 0 | G5: =C5*F5 -> 0 | I5: =C5*H5 -> 0 | J5: =D5+F5+H5 -> 0 | K5: =E5+G5+I5 -> 0
A6: Ala Carte | B6: Spicy Cheesy Chicken | C6: 189 | E6: =C6*D6 -> 0 | G6: =C6*F6 -> 0 | I6: =C6*H6 -> 0 | J6: =D6+F6+H6 -> 0 | K6: =E6+G6+I6 -> 0
A7: Ala Carte | B7: Bam-E | C7: 189 | E7: =C7*D7 -> 0 | G7: =C7*F7 -> 0 | I7: =C7*H7 -> 0 | J7: =D7+F7+H7 -> 0 | K7: =E7+G7+I7 -> 0
A8: Ala Carte | B8: Pork Binagoongan | C8: 189 | E8: =C8*D8 -> 0 | G8: =C8*F8 -> 0 | I8: =C8*H8 -> 0 | J8: =D8+F8+H8 -> 0 | K8: =E8+G8+I8 -> 0
A9: Ala Carte | B9: Pork Sisig | C9: 189 | D9: 1 | E9: =C9*D9 -> 189 | G9: =C9*F9 -> 0 | I9: =C9*H9 -> 0 | J9: =D9+F9+H9 -> 1 | K9: =E9+G9+I9 -> 189
A10: Sizzlers (Unli Rice + 1 Free Drink) | B10: Pork Sisig | C10: 149 | E10: =C10*D10 -> 0 | F10: 1 | G10: =C10*F10 -> 149 | I10: =C10*H10 -> 0 | J10: =D10+F10+H10 -> 1 | K10: =E10+G10+I10 -> 149
A11: Sizzlers (Unli Rice + 1 Free Drink) | B11: Chicken Sisig | C11: 149 | E11: =C11*D11 -> 0 | G11: =C11*F11 -> 0 | I11: =C11*H11 -> 0 | J11: =D11+F11+H11 -> 0 | K11: =E11+G11+I11 -> 0
A12: Sizzlers (Unli Rice + 1 Free Drink) | B12: Squid Sisig | C12: 149 | E12: =C12*D12 -> 0 | G12: =C12*F12 -> 0 | I12: =C12*H12 -> 0 | J12: =D12+F12+H12 -> 0 | K12: =E12+G12+I12 -> 0
A13: Sizzlers (Unli Rice + 1 Free Drink) | B13: Korean Spicy Pork | C13: 149 | E13: =C13*D13 -> 0 | G13: =C13*F13 -> 0 | I13: =C13*H13 -> 0 | J13: =D13+F13+H13 -> 0 | K13: =E13+G13+I13 -> 0
A14: Sizzlers (Unli Rice + 1 Free Drink) | B14: Porkchop | C14: 149 | G14: =C14*F14 -> 0 | I14: =C14*H14 -> 0 | J14: =D14+F14+H14 -> 0 | K14: =E14+G14+I14 -> 0
A15: Sizzlers (Unli Rice + 1 Free Drink) | B15: Pork Liempo | C15: 149 | E15: =C15*D15 -> 0 | G15: =C15*F15 -> 0 | I15: =C15*H15 -> 0 | J15: =D15+F15+H15 -> 0 | K15: =E15+G15+I15 -> 0
A16: Sizzlers (Unli Rice + 1 Free Drink) | B16: Pork steak | C16: 149 | E16: =C16*D16 -> 0 | G16: =C16*F16 -> 0 | I16: =C16*H16 -> 0 | J16: =D16+F16+H16 -> 0 | K16: =E16+G16+I16 -> 0
A17: Sizzlers (Unli Rice + 1 Free Drink) | B17: Beef Steak | C17: 149 | E17: =C17*D17 -> 0 | G17: =C17*F17 -> 0 | I17: =C17*H17 -> 0 | J17: =D17+F17+H17 -> 0 | K17: =E17+G17+I17 -> 0
A18: Sizzlers (Unli Rice + 1 Free Drink) | B18: Burger Steak | C18: 149 | E18: =C18*D18 -> 0 | G18: =C18*F18 -> 0 | I18: =C18*H18 -> 0 | J18: =D18+F18+H18 -> 0 | K18: =E18+G18+I18 -> 0
A19: Sizzlers (Unli Rice + 1 Free Drink) | B19: Fried Chicken | C19: 149 | E19: =C19*D19 -> 0 | F19: 1 | G19: =C19*F19 -> 149 | I19: =C19*H19 -> 0 | J19: =D19+F19+H19 -> 1 | K19: =E19+G19+I19 -> 149
A20: Sizzlers (Unli Rice + 1 Free Drink) | B20: Beef Ala Pobre | C20: 149 | E20: =C20*D20 -> 0 | G20: =C20*F20 -> 0 | I20: =C20*H20 -> 0 | J20: =D20+F20+H20 -> 0 | K20: =E20+G20+I20 -> 0
A21: Sizzlers (Unli Rice + 1 Free Drink) | B21: Fish Fillet | C21: 149 | E21: =C21*D21 -> 0 | G21: =C21*F21 -> 0 | I21: =C21*H21 -> 0 | J21: =D21+F21+H21 -> 0 | K21: =E21+G21+I21 -> 0
A22: Sizzlers (Unli Rice + 1 Free Drink) | B22: Squid rings | C22: 149 | E22: =C22*D22 -> 0 | G22: =C22*F22 -> 0 | I22: =C22*H22 -> 0 | J22: =D22+F22+H22 -> 0 | K22: =E22+G22+I22 -> 0
A23: Classic Cutlets | B23: Fish Cutlet | C23: 159 | D23: 1 | E23: =C23*D23 -> 159 | G23: =C23*F23 -> 0 | I23: =C23*H23 -> 0 | J23: =D23+F23+H23 -> 1 | K23: =E23+G23+I23 -> 159
A24: Classic Cutlets | B24: Pork Cutlet | C24: 159 | D24: 2 | E24: =C24*D24 -> 318 | F24: 1 | G24: =C24*F24 -> 159 | I24: =C24*H24 -> 0 | J24: =D24+F24+H24 -> 3 | K24: =E24+G24+I24 -> 477
A25: Classic Cutlets | B25: Chicken Cutlet | C25: 159 | E25: =C25*D25 -> 0 | F25: 1 | G25: =C25*F25 -> 159 | I25: =C25*H25 -> 0 | J25: =D25+F25+H25 -> 1 | K25: =E25+G25+I25 -> 159
A26: Classic Cutlets | B26: Beef Cutlet | C26: 159 | E26: =C26*D26 -> 0 | G26: =C26*F26 -> 0 | I26: =C26*H26 -> 0 | J26: =D26+F26+H26 -> 0 | K26: =E26+G26+I26 -> 0
A27: Rice Toppings (Fried Rice) | B27: Fish Fillet | C27: 99 | E27: =C27*D27 -> 0 | G27: =C27*F27 -> 0 | I27: =C27*H27 -> 0 | J27: =D27+F27+H27 -> 0 | K27: =E27+G27+I27 -> 0
A28: Rice Toppings (Fried Rice) | B28: Porkchop | C28: 99 | E28: =C28*D28 -> 0 | G28: =C28*F28 -> 0 | I28: =C28*H28 -> 0 | J28: =D28+F28+H28 -> 0 | K28: =E28+G28+I28 -> 0
A29: Rice Toppings (Fried Rice) | B29: Siomai | C29: 99 | E29: =C29*D29 -> 0 | G29: =C29*F29 -> 0 | I29: =C29*H29 -> 0 | J29: =D29+F29+H29 -> 0 | K29: =E29+G29+I29 -> 0
A30: Rice Toppings (Fried Rice) | B30: Sisig | C30: 99 | D30: 1 | E30: =C30*D30 -> 99 | G30: =C30*F30 -> 0 | I30: =C30*H30 -> 0 | J30: =D30+F30+H30 -> 1 | K30: =E30+G30+I30 -> 99
A31: Rice Toppings (Fried Rice) | B31: Chicken Nuggets | C31: 99 | E31: =C31*D31 -> 0 | G31: =C31*F31 -> 0 | I31: =C31*H31 -> 0 | J31: =D31+F31+H31 -> 0 | K31: =E31+G31+I31 -> 0
A32: Appetizers | B32: Egg roll | C32: 149 | E32: =C32*D32 -> 0 | G32: =C32*F32 -> 0 | I32: =C32*H32 -> 0 | J32: =D32+F32+H32 -> 0 | K32: =E32+G32+I32 -> 0
A33: Appetizers | B33: Kimbap | C33: 149 | E33: =C33*D33 -> 0 | G33: =C33*F33 -> 0 | I33: =C33*H33 -> 0 | J33: =D33+F33+H33 -> 0 | K33: =E33+G33+I33 -> 0
A34: Appetizers | B34: Steam Egg | C34: 149 | E34: =C34*D34 -> 0 | G34: =C34*F34 -> 0 | I34: =C34*H34 -> 0 | J34: =D34+F34+H34 -> 0 | K34: =E34+G34+I34 -> 0
A35: Appetizers | B35: Black Noodles | C35: 149 | E35: =C35*D35 -> 0 | G35: =C35*F35 -> 0 | I35: =C35*H35 -> 0 | J35: =D35+F35+H35 -> 0 | K35: =E35+G35+I35 -> 0
A36: Drinks & Extras | B36: Mt dew | C36: 25 | E36: =C36*D36 -> 0 | G36: =C36*F36 -> 0 | I36: =C36*H36 -> 0 | J36: =D36+F36+H36 -> 0 | K36: =E36+G36+I36 -> 0
A37: Drinks & Extras | B37: Pepsi | C37: 20 | D37: 2 | E37: =C37*D37 -> 40 | G37: =C37*F37 -> 0 | I37: =C37*H37 -> 0 | J37: =D37+F37+H37 -> 2 | K37: =E37+G37+I37 -> 40
A38: Drinks & Extras | B38: Bottled Water | C38: 20 | E38: =C38*D38 -> 0 | G38: =C38*F38 -> 0 | I38: =C38*H38 -> 0 | J38: =D38+F38+H38 -> 0 | K38: =E38+G38+I38 -> 0
A39: Drinks & Extras | B39: Plain Rice | C39: 20 | E39: =C39*D39 -> 0 | G39: =C39*F39 -> 0 | I39: =C39*H39 -> 0 | J39: =D39+F39+H39 -> 0 | K39: =E39+G39+I39 -> 0
A40: Drinks & Extras | B40: Garlic Rice | C40: 25 | E40: =C40*D40 -> 0 | G40: =C40*F40 -> 0 | I40: =C40*H40 -> 0 | J40: =D40+F40+H40 -> 0 | K40: =E40+G40+I40 -> 0
...

Sheet DailySummary
A1: Date | B1: Cash Sales | C1: GCash Sales | D1: Foodpanda Sales | E1: Total Sales | F1: Remarks
A2: 45902 | B2: 1800 | C2: 149 | D2: 0 | E2: =SUM(B2:C2:D2) -> 1949
A3: 45903 | B3: 2035 | C3: 457 | D3: 0 | E3: =SUM(B3:C3:D3) -> 2492
A4: 45904 | B4: 1500 | C4: 0 | D4: 338 | E4: =SUM(B4:C4:D4) -> 1838
A5: 45905 | B5: 2978 | C5: 0 | D5: 0 | E5: =SUM(B5:C5:D5) -> 2978
A6: 45906 | B6: 0 | C6: 1023 | D6: 0 | E6: =SUM(B6:C6:D6) -> 1023
A7: 45907 | B7: 0 | C7: 0 | D7: 0 | E7: =SUM(B7:C7:D7) -> 0 | F7: closed
A8: 45908 | B8: 0 | C8: 0 | D8: 0 | E8: =SUM(B8:C8:D8) -> 0 | F8: closed
A9: 45909 | B9: 1000 | C9: 0 | D9: 0 | E9: =SUM(B9:C9:D9) -> 1000
A10: 45910 | B10: 298 | C10: 234 | D10: 0 | E10: =SUM(B10:C10:D10) -> 532
A11: 45911 | B11: 1420 | C11: 0 | D11: 0 | E11: =SUM(B11:C11:D11) -> 1420
A12: 45912 | B12: 0 | C12: 0 | D12: 0 | E12: =SUM(B12:C12:D12) -> 0
A13: 45913 | B13: 1089 | C13: 0 | D13: 0 | E13: =SUM(B13:C13:D13) -> 1089
A14: 45914 | B14: 0 | C14: 0 | D14: 0 | E14: =SUM(B14:C14:D14) -> 0
A15: 45915 | B15: 1613 | C15: 0 | D15: 0 | E15: =SUM(B15:C15:D15) -> 1613
A16: 45916 | B16: 1889 | C16: 0 | D16: 0 | E16: =SUM(B16:C16:D16) -> 1889
A17: 45917 | B17: 1200 | C17: 0 | D17: 567 | E17: =SUM(B17:C17:D17) -> 1767
A18: 45918 | B18: 2150 | C18: 0 | D18: 2126 | E18: =SUM(B18:C18:D18) -> 4276
A19: 45919 | B19: 1200 | C19: 477 | D19: 934 | E19: =SUM(B19:C19:D19) -> 2611
A20: 45920 | B20: 800 | C20: 318 | D20: 0 | E20: =SUM(B20:C20:D20) -> 1118
... A30: 45930 | B30: 1600 | C30: 0 | D30: 0 | E30: =SUM(B30:C30:D30) -> 1600
A31: Total | B31: 29497 | C31: 3495 | D31: 5920 | E31: =SUM(E2:E30) -> 38912
A32: Date | B32: Cash Sales | C32: GCash Sales | D32: Food panda Sales | E32: Total Sales | F32: Remarks
A33: 45931 | B33: 1400 | C33: 0 | D33: 338 | E33: =sum(B33:C33:D33) -> 1738
A34: 45932 | B34: 1900 | C34: 298 | D34: 338 | E34: =sum(B34:C34:D34) -> 2536
A35: 45933 | B35: 659 | C35: 496 | D35: 0 | E35: =sum(B35:C35:D35) -> 1155
A36: 45934 | B36: 576 | C36: 0 | D36: 0 | E36: =sum(B36:C36:D36) -> 576
A37: 45935 | B37: 0 | C37: 0 | D37: 0 | E37: =sum(B37:C37:D37) -> 0
A38: 45936 | B38: 1490 | C38: 149 | D38: 0 | E38: =sum(B38:C38:D38) -> 1639
A39: 45937 | B39: 0 | C39: 0 | D39: 0 | E39: =sum(B39:C39:D39) -> 0
A40: 45938 | B40: 850 | C40: 0 | D40: 149 | E40: =sum(B40:C40:D40) -> 999
A41: 45939 | B41: 567 | C41: 447 | D41: 0 | E41: =sum(B41:C41:D41) -> 1014
A42: 45940 | B42: 500 | C42: 0 | D42: 0 | E42: =sum(B42:C42:D42) -> 500
A43: 45941 | B43: 900 | C43: 0 | D43: 0 | E43: =sum(B43:C43:D43) -> 900
A44: 45942 | B44: 0 | C44: 0 | D44: 0 | E44: =sum(B44:C44:D44) -> 0 | F44: closed
A45: 45943 | B45: 412 | C45: 0 | D45: 0 | E45: =sum(B45:C45:D45) -> 412
A46: 45944 | B46: 400 | C46: 0 | D46: 0 | E46: =sum(B46:C46:D46) -> 400
A47: 45945 | B47: 450 | C47: 0 | D47: 298 | E47: =sum(B47:C47:D47) -> 748
A48: 45946 | B48: 760 | C48: 0 | D48: 1268 | E48: =sum(B48:C48:D48) -> 2028
A49: 45947 | B49: 308 | C49: 618 | D49: 0 | E49: =sum(B49:C49:D49) -> 926
...

Sheet Inventory
A1: Date | B1: Item | C1: Category | D1: Quantity | E1: Unit | F1: Cost per Unit (₱) | G1: Total Cost (₱) | H1: Supplier / Store | I1: Notes
A2: 45903 | B2: lamas, dishwashing, sugar | C2: supplies | G2: 301
A3: 45905 | B3: egg, softdrinks | C3: supplies | G3: 1119
A4: 45912 | B4: pork, chicken | C4: supplies | G4: 1440
A5: 45913 | B5: softdrinks | C5: supplies | G5: 870
A6: 45924 | B6: belly, porkchop, c.breast, carrots, pepino, cabbage, cheese, vetsin, calamansi, spring onions, mantika, itlog | C6: supplies | G6: 3290
A7: 45926 | B7: softdrinks, sugar | C7: supplies | G7: 1469
A8: 45934 | B8: egg, rice | C8: supplies | G8: 769
A9: 45938 | B9: bugas, parcel(476), Aldrin(700) | C9: supplies | G9: 1309 | I9: includes staff CA Aldrin 700
A10: 45941 | B10: softdrinks, egg, springonions | C10: supplies | G10: 1860
A11: 45942 | B11: vetsin, dishwashing, Aldrin(500) | C11: supplies | G11: 575 | I11: includes staff CA Aldrin 500
A12: 45950 | B12: SM (2,930), Libertad (2,690) | C12: supplies | G12: 5620 | I12: SM + Libertad
A13: 45952 | B13: dishwashing | C13: supplies | G13: 45
A14: 45953 | B14: Water (120), Softdrinks (1160) | C14: supplies | G14: 1280
A15: 45958 | B15: Rice, pork | C15: supplies | G15: 650
A16: 45960 | B16: SM (Meat, ramen, sauce) | C16: supplies | G16: 1759 | I16: SM
A17: 45970 | B17: Grocery | C17: supplies | G17: 2000 | I17: payment: Card
A18: 45978 | B18: Egg, Calamansi | C18: supplies | G18: 580
A19: 45980 | B19: Rice 75, Grocery 2000 | C19: supplies | G19: 2075
A20: 45987 | B20: Egg 2 tray(480), Pork (243), Lamas (240) | C20: supplies | G20: 963
A21: 45991 | B21: Meat | C21: supplies | G21: 2000 | I21: payment: Atome
A22: 46001 | B22: tarp and takeoutboxes | C22: supplies | G22: 1885
A23: 46004 | B23: mt dew. 3 case | C23: supplies | D23: 3 | E23: case | G23: 870
A24: 46004 | B24: egg | C24: supplies | G24: 270
A25: 46004 | B25: pork | C25: supplies | G25: 500
A26: 46004 | B26: chicken | C26: supplies | G26: 206
A27: 46004 | B27: cabbage, carrots,salt | C27: supplies | G27: 340
A28: 46004 | B28: dry peas and corn | C28: supplies | G28: 71
A29: 46006 | B29: rice | C29: supplies | G29: 150
A30: 46009 | B30: beef | C30: supplies | D30: 1.3 | E30: kg | G30: 709
A31: 46009 | B31: rice | C31: supplies | D31: 2 | E31: kg | G31: 104
A32: 46009 | B32: pork | C32: supplies | D32: 0.5 | E32: kg | G32: 170
A33: 46013 | B33: pork | C33: supplies | D33: 0.8 | E33: kg | G33: 280
A34: 46013 | B34: fish fillet | C34: supplies | D34: 3 | E34: pcs | G34: 114
A35: 46013 | B35: butter | C35: supplies | D35: 2 | E35: bar | G35: 108
A36: 46013 | B36: chicken wings | C36: supplies | D36: 1 | E36: kg | G36: 259
A37: 46013 | B37: flour,cabbage,hotdog,trapo | C37: supplies | G37: 338
A38: 46014 | B38: Onion, carrots | C38: supplies | G38: 100

Sheet Expenses
A1: Date | B1: Category | C1: Description | D1: Payment Method | E1: Amount (₱) | F1: Remarks
A2: 45915 | B2: utilities | C2: electricity bill, water | D2: gcash | E2: 5982.22
A3: 45917 | B3: staff | C3: Aldrin | D3: gcash | E3: 4800
A4: 45925 | B4: staff | C4: Aldrin | D4: cash | E4: 800
A5: 45930 | B5: staff | C5: Aldrin | D5: cash | E5: 7200
A6: 45944 | B6: staff | C6: cash advance (Ken) | D6: cash | E6: 150
A7: 45945 | B7: staff | C7: Ken (1500), Aldrin (4500) | D7: cash | E7: 5500
A8: 45947 | B8: staff | C8: Ken (900) | D8: cash | E8: 900
A9: 45948 | B9: staff | C9: Ken (450) | D9: cash | E9: 450
A10: 45951 | B10: staff | C10: Aldrin (600) CA | D10: cash | E10: 600
A11: 45954 | B11: staff | C11: CA Ken (400), Aldrin (200) | D11: cash | E11: 600
A12: 45955 | B12: supplies | C12: CA Aldrin (500), Receipt (171) | D12: cash | E12: 671
A13: 45957 | B13: supplies | C13: Rice, Aldrin (270), Ken (150) | D13: cash | E13: 570
... A26: 46008 | B26: utilities | C26: wifi | D26: cash | E26: 1000
A27: 46008 | B27: staff | C27: aldrin sweldo 4260 | D27: cash
A28: 46009 | B28: supplies | C28: Pork, sugar,green peas, rice, gochujhang | D28: cash | E28: 664
A29: 46009 | B29: supplies | C29: Beef(659) tissue(50) | D29: FP sales
A30: 46013 | B30: supplies | C30: meat, veges, bugas, trapo | D30: cash | E30: 1401
A31: 46013 | B31: staff | C31: guard | D31: cash | E31: 800
B32: familyv expenses | C32: chicken, pork,grocery, athena | D32: cash | E32: 704

Sheet StockInOut
A1: Date | B1: Item | C1: Type | D1: Qty | E1: Unit | F1: Reason | G1: Reference | H1: Notes
A2: 46003 | B2: egg | C2: IN | D2: 2 | E2: tray | F2: purchase
A3: 46004 | B3: egg | C3: IN | D3: 1 | E3: tray | F3: purchase
A4: 46004 | B4: pork | C4: IN | D4: 1.5 | E4: PO | F4: purchase
A5: 46004 | B5: softdrinks | C5: IN | D5: 74 | E5: pcs | F5: purchase
A6: 46004 | B6: chicken | C6: IN | D6: 1 | E6: kg | F6: purchase
A7: 46006 | B7: rice | C7: IN | D7: 1 | E7: kg | F7: purchase
A8: 46008 | B8: chicken | C8: IN | D8: 1.5 | E8: kg | F8: purchase
A9: 46008 | B9: pork | C9: IN | D9: 1.5 | E9: kg | F9: purchase
A10: 46009 | B10: Beef | C10: IN | D10: 900 | E10: g | F10: purchase
A11: 46009 | B11: Pork | C11: IN | D11: 0.5 | E11: kg | F11: Purchase
A12: 46009 | B12: Rice | C12: IN | D12: 2 | E12: kg | F12: Purchase
A13: 46013 | B13: chicken wings | C13: IN | D13: 1 | E13: kg | F13: Purchase
... A16: 46015 | B16: Fish fillet | C16: IN | D16: 3 | E16: pcs | F16: Purchase
A17: 46016
A18: 46017
A19: 46018
A20: 46019
A21: 46020
A22: 46021
A23: 46022
A24: 46023
A25: 46024
A26: 46025
A27: 46026
A28: 46027
... A43: 46042

Sheet StockBalance
A1: Item | B1: Unit | C1: Total In | D1: Total Out | E1: Balance
A2: Pork | B2: kg | C2: =IFERROR(SUMIFS(StockInOut!$D:$D,StockInOut!$B:$B,$A2,StockInOut!$C:$C,"IN"),0) -> 4 | D2: =IFERROR(SUMIFS(StockInOut!$D:$D,StockInOut!$B:$B,$A2,StockInOut!$C:$C,"OUT"),0) -> 0 | E2: =C2-D2 -> 4
A3: Chicken | B3: kg | C3: =IFERROR(SUMIFS(StockInOut!$D:$D,StockInOut!$B:$B,$A3,StockInOut!$C:$C,"IN"),0) -> 2.5 | D3: =IFERROR(SUMIFS(StockInOut!$D:$D,StockInOut!$B:$B,$A3,StockInOut!$C:$C,"OUT"),0) -> 0 | E3: =C3-D3 -> 2.5
A4: Beef | B4: kg | C4: =IFERROR(SUMIFS(StockInOut!$D:$D,StockInOut!$B:$B,$A4,StockInOut!$C:$C,"IN"),0) -> 900 | D4: =IFERROR(SUMIFS(StockInOut!$D:$D,StockInOut!$B:$B,$A4,StockInOut!$C:$C,"OUT"),0) -> 0 | E4: =C4-D4 -> 900
A5: Squid | B5: kg | C5: =IFERROR(SUMIFS(StockInOut!$D:$D,StockInOut!$B:$B,$A5,StockInOut!$C:$C,"IN"),0) -> 0 | D5: =IFERROR(SUMIFS(StockInOut!$D:$D,StockInOut!$B:$B,$A5,StockInOut!$C:$C,"OUT"),0) -> 0 | E5: =C5-D5 -> 0
A6: Rice | B6: kg | C6: =IFERROR(SUMIFS(StockInOut!$D:$D,StockInOut!$B:$B,$A6,StockInOut!$C:$C,"IN"),0) -> 8 | D6: =IFERROR(SUMIFS(StockInOut!$D:$D,StockInOut!$B:$B,$A6,StockInOut!$C:$C,"OUT"),0) -> 0 | E6: =C6-D6 -> 8
A7: Egg | B7: tray | C7: =IFERROR(SUMIFS(StockInOut!$D:$D,StockInOut!$B:$B,$A7,StockInOut!$C:$C,"IN"),0) -> 3 | D7: =IFERROR(SUMIFS(StockInOut!$D:$D,StockInOut!$B:$B,$A7,StockInOut!$C:$C,"OUT"),0) -> 0 | E7: =C7-D7 -> 3
A8: Softdrinks | B8: bottle | C8: =IFERROR(SUMIFS(StockInOut!$D:$D,StockInOut!$B:$B,$A8,StockInOut!$C:$C,"IN"),0) -> 74 | D8: =IFERROR(SUMIFS(StockInOut!$D:$D,StockInOut!$B:$B,$A8,StockInOut!$C:$C,"OUT"),0) -> 0 | E8: =C8-D8 -> 74
A9: Oil | B9: L | C9: =IFERROR(SUMIFS(StockInOut!$D:$D,StockInOut!$B:$B,$A9,StockInOut!$C:$C,"IN"),0) -> 0 | D9: =IFERROR(SUMIFS(StockInOut!$D:$D,StockInOut!$B:$B,$A9,StockInOut!$C:$C,"OUT"),0) -> 0 | E9: =C9-D9 -> 0

Sheet MonthlySummary
A1: Month | B1: Sales (Summary!E) | C1: Supplies (Inventory!G) | D1: Overhead (Expenses!E) | E1: Total Expenses | F1: Profit | G1: Notes
A2: 45901 | B2: =SUMIFS(DailySummary!$E:$E,DailySummary!$A:$A,">="&EOMONTH($A2,-1)+1,DailySummary!$A:$A,"<="&EOMONTH($A2,0)) -> 38912 | C2: =SUMIFS(Inventory!$G:$G,Inventory!$A:$A,">="&EOMONTH($A2,-1)+1,Inventory!$A:$A,"<="&EOMONTH($A2,0)) -> 8489 | D2: =SUMIFS(Expenses!$E:$E,Expenses!$A:$A,">="&EOMONTH($A2,-1)+1,Expenses!$A:$A,"<="&EOMONTH($A2,0)) -> 18782.22 | E2: =C2+D2 -> 27271.22 | F2: =B2-E2 -> 11640.78
A3: 45931 | B3: =SUMIFS(DailySummary!$E:$E,DailySummary!$A:$A,">="&EOMONTH($A3,-1)+1,DailySummary!$A:$A,"<="&EOMONTH($A3,0)) -> 28696 | C3: =SUMIFS(Inventory!$G:$G,Inventory!$A:$A,">="&EOMONTH($A3,-1)+1,Inventory!$A:$A,"<="&EOMONTH($A3,0)) -> 13867 | D3: =SUMIFS(Expenses!$E:$E,Expenses!$A:$A,">="&EOMONTH($A3,-1)+1,Expenses!$A:$A,"<="&EOMONTH($A3,0)) -> 9441 | E3: =C3+D3 -> 23308 | F3: =B3-E3 -> 5388
A4: 45962 | B4: =SUMIFS(DailySummary!$E:$E,DailySummary!$A:$A,">="&EOMONTH($A4,-1)+1,DailySummary!$A:$A,"<="&EOMONTH($A4,0)) -> 26536 | C4: =SUMIFS(Inventory!$G:$G,Inventory!$A:$A,">="&EOMONTH($A4,-1)+1,Inventory!$A:$A,"<="&EOMONTH($A4,0)) -> 7618 | D4: =SUMIFS(Expenses!$E:$E,Expenses!$A:$A,">="&EOMONTH($A4,-1)+1,Expenses!$A:$A,"<="&EOMONTH($A4,0)) -> 7819 | E4: =C4+D4 -> 15437 | F4: =B4-E4 -> 11099
A5: 45992 | B5: =SUMIFS(DailySummary!$E:$E,DailySummary!$A:$A,">="&EOMONTH($A5,-1)+1,DailySummary!$A:$A,"<="&EOMONTH($A5,0)) -> 17052 | C5: =SUMIFS(Inventory!$G:$G,Inventory!$A:$A,">="&EOMONTH($A5,-1)+1,Inventory!$A:$A,"<="&EOMONTH($A5,0)) -> 6474 | D5: =SUMIFS(Expenses!$E:$E,Expenses!$A:$A,">="&EOMONTH($A5,-1)+1,Expenses!$A:$A,"<="&EOMONTH($A5,0)) -> 5890 | E5: =C5+D5 -> 12364 | F5: =B5-E5 -> 4688
A6: 46023 | B6: =SUMIFS(DailySummary!$E:$E,DailySummary!$A:$A,">="&EOMONTH($A6,-1)+1,DailySummary!$A:$A,"<="&EOMONTH($A6,0)) -> 0 | C6: =SUMIFS(Inventory!$G:$G,Inventory!$A:$A,">="&EOMONTH($A6,-1)+1,Inventory!$A:$A,"<="&EOMONTH($A6,0)) -> 0 | D6: =SUMIFS(Expenses!$E:$E,Expenses!$A:$A,">="&EOMONTH($A6,-1)+1,Expenses!$A:$A,"<="&EOMONTH($A6,0)) -> 0 | E6: =C6+D6 -> 0 | F6: =B6-E6 -> 0
A7: 46082 | B7: =SUMIFS(DailySummary!$E:$E,DailySummary!$A:$A,">="&EOMONTH($A7,-1)+1,DailySummary!$A:$A,"<="&EOMONTH($A7,0)) -> 0 | C7: =SUMIFS(Inventory!$G:$G,Inventory!$A:$A,">="&EOMONTH($A7,-1)+1,Inventory!$A:$A,"<="&EOMONTH($A7,0)) -> 0 | D7: =SUMIFS(Expenses!$E:$E,Expenses!$A:$A,">="&EOMONTH($A7,-1)+1,Expenses!$A:$A,"<="&EOMONTH($A7,0)) -> 0 | E7: =C7+D7 -> 0 | F7: =B7-E7 -> 0
A8: 46113 | B8: =SUMIFS(DailySummary!$E:$E,DailySummary!$A:$A,">="&EOMONTH($A8,-1)+1,DailySummary!$A:$A,"<="&EOMONTH($A8,0)) -> 0 | C8: =SUMIFS(Inventory!$G:$G,Inventory!$A:$A,">="&EOMONTH($A8,-1)+1,Inventory!$A:$A,"<="&EOMONTH($A8,0)) -> 0 | D8: =SUMIFS(Expenses!$E:$E,Expenses!$A:$A,">="&EOMONTH($A8,-1)+1,Expenses!$A:$A,"<="&EOMONTH($A8,0)) -> 0 | E8: =C8+D8 -> 0 | F8: =B8-E8 -> 0
A9: 46143 | B9: =SUMIFS(DailySummary!$E:$E,DailySummary!$A:$A,">="&EOMONTH($A9,-1)+1,DailySummary!$A:$A,"<="&EOMONTH($A9,0)) -> 0 | C9: =SUMIFS(Inventory!$G:$G,Inventory!$A:$A,">="&EOMONTH($A9,-1)+1,Inventory!$A:$A,"<="&EOMONTH($A9,0)) -> 0 | D9: =SUMIFS(Expenses!$E:$E,Expenses!$A:$A,">="&EOMONTH($A9,-1)+1,Expenses!$A:$A,"<="&EOMONTH($A9,0)) -> 0 | E9: =C9+D9 -> 0 | F9: =B9-E9 -> 0
